<?xml version="1.0" encoding="utf-8" ?>
<!-- This URDF was automatically created by SolidWorks to URDF Exporter! Originally created by Stephen Brawner (brawner@gmail.com) 
     Commit Version: 1.6.0-4-g7f85cfe  Build Version: 1.6.7995.38578
     For more information, please see http://wiki.ros.org/sw_urdf_exporter -->
<robot name="knighttime_description">
    <link name="base_link">
        <inertial>
            <origin xyz="-4.16447055162402E-17 6.55581426343069E-17 0.126710454365849" rpy="0 0 0" />
            <mass value="1.27012028561213" />
            <inertia ixx="0.00407454547284583" ixy="1.70217144461307E-20" ixz="2.00721692769744E-05" iyy="0.00877718974084694" iyz="2.16369115604361E-20" izz="0.00471118000553721" />
        </inertial>
        <visual>
            <origin xyz="0 0 0" rpy="0 0 0" />
            <geometry>
                <mesh filename="package://knighttime_description/meshes/base_link.STL" />
            </geometry>
            <material name="">
                <color rgba="0.752941176470588 0.752941176470588 0.752941176470588 1" />
            </material>
        </visual>
        <collision>
            <origin xyz="0 0 0" rpy="0 0 0" />
            <geometry>
                <mesh filename="package://knighttime_description/meshes/base_link.STL" />
            </geometry>
        </collision>
    </link>
    <link name="main_mast">
        <inertial>
            <origin xyz="-2.69904669733839E-05 -9.99896965886688E-07 0.522377111502143" rpy="0 0 0" />
            <mass value="2.93521012462161" />
            <inertia ixx="0.27622236196956" ixy="2.66165269670605E-10" ixz="-0.000104045614467622" iyy="0.271514723325184" iyz="-1.14857392516794E-06" izz="0.00662016432728772" />
        </inertial>
        <visual>
            <origin xyz="0 0 0" rpy="0 0 0" />
            <geometry>
                <mesh filename="package://knighttime_description/meshes/main_mast.STL" />
            </geometry>
            <material name="">
                <color rgba="0.752941176470588 0.752941176470588 0.752941176470588 1" />
            </material>
        </visual>
        <collision>
            <origin xyz="0 0 0" rpy="0 0 0" />
            <geometry>
                <mesh filename="package://knighttime_description/meshes/main_mast.STL" />
            </geometry>
        </collision>
    </link>
    <joint name="base_link_to_main_mast" type="continuous">
        <origin xyz="0 0 0.24511" rpy="0 0 0" />
        <parent link="base_link" />
        <child link="main_mast" />
        <axis xyz="0 1 0" />
    </joint>
    <link name="second_stage">
        <inertial>
            <origin xyz="-3.54992298224833E-16 2.22485749511977E-16 -0.20537398340882" rpy="0 0 0" />
            <mass value="0.836825875518592" />
            <inertia ixx="0.0207383995013211" ixy="-2.4071703608376E-18" ixz="6.5182228435467E-18" iyy="0.0187889584740115" iyz="3.10142844521603E-19" izz="0.00256143928759479" />
        </inertial>
        <visual>
            <origin xyz="0 0 0" rpy="0 0 0" />
            <geometry>
                <mesh filename="package://knighttime_description/meshes/second_stage.STL" />
            </geometry>
            <material name="">
                <color rgba="0.752941176470588 0.752941176470588 0.752941176470588 1" />
            </material>
        </visual>
        <collision>
            <origin xyz="0 0 0" rpy="0 0 0" />
            <geometry>
                <mesh filename="package://knighttime_description/meshes/second_stage.STL" />
            </geometry>
        </collision>
    </link>
    <joint name="main_mast_to_second_stage" type="continuous">
        <origin xyz="0 0 0.8763" rpy="0 0 0" />
        <parent link="main_mast" />
        <child link="second_stage" />
        <axis xyz="0 1 0" />
    </joint>
    <transmission name="trans_base_link_to_main_mast">
        <type>transmission_interface/SimpleTransmission</type>
        <joint name="base_link_to_main_mast">
            <hardwareInterface>hardware_interface/PositionJointInterface</hardwareInterface>
        </joint>
        <actuator name="base_link_to_main_mast_motor">
            <hardwareInterface>hardware_interface/PositionJointInterface</hardwareInterface>
            <mechanicalReduction>1</mechanicalReduction>
        </actuator>
    </transmission>
    <transmission name="trans_main_mast_to_second_stage">
        <type>transmission_interface/SimpleTransmission</type>
        <joint name="main_mast_to_second_stage">
            <hardwareInterface>hardware_interface/PositionJointInterface</hardwareInterface>
        </joint>
        <actuator name="main_mast_to_second_stage_motor">
            <hardwareInterface>hardware_interface/PositionJointInterface</hardwareInterface>
            <mechanicalReduction>1</mechanicalReduction>
        </actuator>
    </transmission>
    <gazebo>
        <plugin name="gazebo_ros_control">
            <robotNamespace>/</robotNamespace>
        </plugin>
    </gazebo>
</robot>

